{"trial_id": "0000", "hyperparameters": {"space": [{"class_name": "Int", "config": {"name": "num_layers", "default": null, "conditions": [], "min_value": 1, "max_value": 3, "step": 1, "sampling": "linear"}}, {"class_name": "Int", "config": {"name": "hidden_size", "default": null, "conditions": [], "min_value": 32, "max_value": 128, "step": 32, "sampling": "linear"}}, {"class_name": "Float", "config": {"name": "dropout_rate", "default": 0.0, "conditions": [], "min_value": 0.0, "max_value": 0.5, "step": 0.1, "sampling": "linear"}}], "values": {"num_layers": 3, "hidden_size": 64, "dropout_rate": 0.2, "tuner/epochs": 2, "tuner/initial_epoch": 0, "tuner/bracket": 2, "tuner/round": 0}}, "metrics": {"metrics": {}}, "score": null, "best_step": 0, "status": "FAILED", "message": "Traceback (most recent call last):\n  File \"c:\\Users\\azizu\\anaconda3\\envs\\test2_COMP3420\\lib\\site-packages\\keras_tuner\\src\\engine\\base_tuner.py\", line 274, in _try_run_and_update_trial\n    self._run_and_update_trial(trial, *fit_args, **fit_kwargs)\n  File \"c:\\Users\\azizu\\anaconda3\\envs\\test2_COMP3420\\lib\\site-packages\\keras_tuner\\src\\engine\\base_tuner.py\", line 239, in _run_and_update_trial\n    results = self.run_trial(trial, *fit_args, **fit_kwargs)\n  File \"c:\\Users\\azizu\\anaconda3\\envs\\test2_COMP3420\\lib\\site-packages\\keras_tuner\\src\\tuners\\hyperband.py\", line 427, in run_trial\n    return super().run_trial(trial, *fit_args, **fit_kwargs)\n  File \"c:\\Users\\azizu\\anaconda3\\envs\\test2_COMP3420\\lib\\site-packages\\keras_tuner\\src\\engine\\tuner.py\", line 314, in run_trial\n    obj_value = self._build_and_fit_model(trial, *args, **copied_kwargs)\n  File \"c:\\Users\\azizu\\anaconda3\\envs\\test2_COMP3420\\lib\\site-packages\\keras_tuner\\src\\engine\\tuner.py\", line 233, in _build_and_fit_model\n    results = self.hypermodel.fit(hp, model, *args, **kwargs)\n  File \"c:\\Users\\azizu\\anaconda3\\envs\\test2_COMP3420\\lib\\site-packages\\keras_tuner\\src\\engine\\hypermodel.py\", line 149, in fit\n    return model.fit(*args, **kwargs)\n  File \"c:\\Users\\azizu\\anaconda3\\envs\\test2_COMP3420\\lib\\site-packages\\keras\\utils\\traceback_utils.py\", line 70, in error_handler\n    raise e.with_traceback(filtered_tb) from None\n  File \"C:\\Users\\azizu\\AppData\\Local\\Temp\\__autograph_generated_filetmoqqdu5.py\", line 15, in tf__train_function\n    retval_ = ag__.converted_call(ag__.ld(step_function), (ag__.ld(self), ag__.ld(iterator)), None, fscope)\nValueError: in user code:\n\n    File \"c:\\Users\\azizu\\anaconda3\\envs\\test2_COMP3420\\lib\\site-packages\\keras\\engine\\training.py\", line 1160, in train_function  *\n        return step_function(self, iterator)\n    File \"c:\\Users\\azizu\\anaconda3\\envs\\test2_COMP3420\\lib\\site-packages\\keras\\engine\\training.py\", line 1146, in step_function  **\n        outputs = model.distribute_strategy.run(run_step, args=(data,))\n    File \"c:\\Users\\azizu\\anaconda3\\envs\\test2_COMP3420\\lib\\site-packages\\keras\\engine\\training.py\", line 1135, in run_step  **\n        outputs = model.train_step(data)\n    File \"c:\\Users\\azizu\\anaconda3\\envs\\test2_COMP3420\\lib\\site-packages\\keras\\engine\\training.py\", line 994, in train_step\n        loss = self.compute_loss(x, y, y_pred, sample_weight)\n    File \"c:\\Users\\azizu\\anaconda3\\envs\\test2_COMP3420\\lib\\site-packages\\keras\\engine\\training.py\", line 1052, in compute_loss\n        return self.compiled_loss(\n    File \"c:\\Users\\azizu\\anaconda3\\envs\\test2_COMP3420\\lib\\site-packages\\keras\\engine\\compile_utils.py\", line 265, in __call__\n        loss_value = loss_obj(y_t, y_p, sample_weight=sw)\n    File \"c:\\Users\\azizu\\anaconda3\\envs\\test2_COMP3420\\lib\\site-packages\\keras\\losses.py\", line 152, in __call__\n        losses = call_fn(y_true, y_pred)\n    File \"c:\\Users\\azizu\\anaconda3\\envs\\test2_COMP3420\\lib\\site-packages\\keras\\losses.py\", line 272, in call  **\n        return ag_fn(y_true, y_pred, **self._fn_kwargs)\n    File \"c:\\Users\\azizu\\anaconda3\\envs\\test2_COMP3420\\lib\\site-packages\\keras\\losses.py\", line 1990, in categorical_crossentropy\n        return backend.categorical_crossentropy(\n    File \"c:\\Users\\azizu\\anaconda3\\envs\\test2_COMP3420\\lib\\site-packages\\keras\\backend.py\", line 5529, in categorical_crossentropy\n        target.shape.assert_is_compatible_with(output.shape)\n\n    ValueError: Shapes (32, 10) and (32, 64) are incompatible\n\n"}